Workbook

Sheet CARE SHEET
A1: Age Band | B1: Age From | C1: Age To | D1: Sum Insured | E1: Cover Type | F1: No. of Members | G1: No. of Adults | H1: No. of Children | I1: Term | J1: zone | K1: COMBINATIO | L1: ROW NO | M1: COLUMN NO | N1: APPLICABLE ARRAY | S1: =VLOOKUP('CALCULATOR CARE V6'!F2,DROPDOWN!K:L,2,0) -> 18-24 | T1: =IF(R4="1+0",V5,V4) -> 4 | U1: RED IN PED | X1: 1A | AA1: Zone 1 | AX1: ZONE- 1A | BU1: ZONE 2 | CO1: ZONE 3
A2: 00-04 | B2: 0 years | C2: 4 years | D2: 5 | E2: INDIVIDUAL | F2: 1 | H2: 1 | I2: 1 | J2: Zone 1 | K2: =G2&"+"&H2 -> +1 | L2: =VLOOKUP(A2,'ZONE 1 PREMIUM'!$A$3:$M$16,13,0) -> 2 | M2: =VLOOKUP(D2,DROPDOWN!B:C,2,0) -> 4 | N2: =VLOOKUP(K2,$AQ$3:$AR$12,2,0) -> #N/A | O2: 3298.4569 | S2: =VLOOKUP('CALCULATOR CARE V6'!E2,DROPDOWN!K:L,2,0) -> 18-24 | T2: =IF(R4="1+0",U5,U4) -> 4 | U2: =VLOOKUP(S2,DROPDOWN!L20:M110,2,0) -> Upto 45 Years | Y2: Care 3 | AA2: Care 4 | AD2: Care 5 | AI2: Care 6 | AL2: Care 7 | AQ2: ARRAY | AT2: 1A | AV2: Care 3 | AX2: Care 4 | BA2: Care 5 | BF2: Care 6 | BI2: Care 7 | BN2: ARRAY | BQ2: 1A | BS2: Care 3 | BU2: Care 4 | BX2: Care 5 | CC2: Care 6 | CF2: Care 7 | CK2: ARRAY | CN2: 1A | CP2: Care 3 | CR2: Care 4 | CU2: Care 5 | CZ2: Care 6 | DC2: Care 7
A3: 05-17 | B3: 5 years | C3: 17 years | D3: 5 | E3: INDIVIDUAL | F3: 1 | G3: 1 | H3: 0 | I3: 1 | J3: Zone 1 | K3: 1+0 | L3: =VLOOKUP(A3,'ZONE 1 PREMIUM'!$A$3:$M$16,13,0) -> 3 | M3: =VLOOKUP(D3,DROPDOWN!B:C,2,0) -> 4 | N3: =VLOOKUP(K3,$AQ$3:$AR$12,2,0) -> X3:AP16 | O3: =INDEX(INDIRECT(N3),L3,M3) -> 5817.85 | S3: =VLOOKUP('CALCULATOR CARE V6'!B2,DROPDOWN!K:L,2,0) -> 18-24 | T3: =VLOOKUP('CALCULATOR CARE V6'!B6,DROPDOWN!A2:B19,2,0) -> 600 | U3: =VLOOKUP(S1,DROPDOWN!L20:M110,2,0) -> Upto 45 Years | X3: Age-Band/ SI | Y3: 3L | Z3: 4L | AA3: 5L | AB3: 7L | AC3: 10L | AD3: 15L | AE3: 20L | AF3: 25L | AG3: 30L | AH3: 40L | AI3: 50L | AJ3: 60L | AK3: 75L | AL3: 1 CR | AM3: 1.5 CR | AN3: 2 CR | AO3: 3 CR | AP3: 6 CR | AQ3: 1+0 | AR3: X3:AP16 | AU3: Age-Band/ SI | AV3: 3L | AW3: 4L | AX3: 5L | AY3: 7L | AZ3: 10L | BA3: 15L | BB3: 20L | BC3: 25L | BD3: 30L | BE3: 40L | BF3: 50L | BG3: 60L | BH3: 75L | BI3: 1 CR | BJ3: 1.5 CR | BK3: 2 CR | BL3: 3 CR | BM3: 6 CR | BN3: 1+0 | BO3: AU3:BM16 | BR3: Age-Band/ SI | BS3: 3L | BT3: 4L | BU3: 5L | BV3: 7L | BW3: 10L | BX3: 15L | BY3: 20L | BZ3: 25L | CA3: 30L | CB3: 40L | CC3: 50L | CD3: 60L | CE3: 75L | CF3: 1 CR | CG3: 1.5 CR | CH3: 2 CR | CI3: 3 CR | CJ3: 6 CR | CK3: 1+0 | CL3: BR3:CJ16 | CO3: Age-Band/ SI | CP3: 3L | CQ3: 4L | CR3: 5L | CS3: 7L | CT3: 10L | CU3: 15L | CV3: 20L | CW3: 25L | CX3: 30L | CY3: 40L | CZ3: 50L | DA3: 60L | DB3: 75L | DC3: 1 CR | DD3: 1.5 CR | DE3: 2 CR | DF3: 3 CR | DG3: 6 CR | DH3: ARRAY
A4: 18-24 | B4: 18 Years | C4: 24 Years | D4: 5 | E4: INDIVIDUAL | F4: 1 | G4: 1 | H4: 0 | I4: 1 | J4: Zone 1 | K4: =G4&"+"&H4 -> 1+0 | L4: =VLOOKUP(A4,'ZONE 1 PREMIUM'!$A$3:$M$16,13,0) -> 4 | M4: =VLOOKUP(D4,DROPDOWN!B:C,2,0) -> 4 | N4: =VLOOKUP(K4,$AQ$3:$AR$12,2,0) -> X3:AP16 | O4: =INDEX(INDIRECT(N4),L4,M4) -> 15584.8 | Q4: COMBINATIO | R4: ='CALCULATOR CARE V6'!B3&"+"&'CALCULATOR CARE V6'!B4 -> 1+0 | U4: =VLOOKUP(S2,DROPDOWN!O15:Q27,3,0) -> 2 | V4: =VLOOKUP(S1,DROPDOWN!O15:Q27,3,0) -> 2 | X4: 00-04 | Y4: 5413.05 | Z4: 6458.4 | AA4: 7586.55 | AB4: 8270.8 | AC4: 8898.7 | AD4: 10383.35 | AE4: 11302.2 | AF4: 12080.75 | AG4: 13475.7 | AH4: 16733.65 | AI4: 25731.25 | AJ4: 32788.8 | AK4: 40684.7 | AL4: 64608.15 | AM4: 76854.5 | AN4: 90276.15 | AO4: 105751.7 | AP4: 141420.1 | AQ4: 1+1 | AR4: X20:AP31 | AU4: 00-04 | AV4: 4806 | AW4: 5733 | AX4: 6730.875 | AY4: 7337.25 | AZ4: 7893 | BA4: 9208.125 | BB4: 10021.5 | BC4: 10711.125 | BD4: 11946.375 | BE4: 14832 | BF4: 22799.25 | BG4: 29048.625 | BH4: 36040.5 | BI4: 58054.5 | BJ4: 68899.5 | BK4: 80784 | BL4: 94488.75 | BM4: 126074.25 | BN4: 1+1 | BO4: AU20:BM31 | BR4: 00-04 | BS4: 4436.3 | BT4: 5289.9 | BU4: 6209.5 | BV4: 6768.3 | BW4: 7280.9 | BX4: 8492 | BY4: 9242.2 | BZ4: 9876.9 | CA4: 11015.4 | CB4: 13674.1 | CC4: 21016.6 | CD4: 26775.1 | CE4: 33218.9 | CF4: 53941.8 | CG4: 63935.3 | CH4: 74886.9 | CI4: 87516 | CJ4: 116623.1 | CK4: 1+1 | CL4: BR20:CJ31 | CO4: 00-04 | CP4: 4086.41 | CQ4: 4871.21 | CR4: 5717.05 | CS4: 6230.44 | CT4: 6701.32 | CU4: 7815.3 | CV4: 8505.27 | CW4: 9089.51 | CX4: 10135.91 | CY4: 12580.78 | CZ4: 19332.24 | DA4: 24627.46 | DB4: 30552.7 | DC4: 50049.53 | DD4: 59239.32 | DE4: 69308.74 | DF4: 80921.6 | DG4: 107686.55 | DH4: 1+0 | DI4: CO3:DG16
A5: 25-35 | B5: 25 Years | C5: 35 Years | D5: 5 | E5: INDIVIDUAL | F5: 1 | G5: 1 | H5: 0 | I5: 1 | J5: Zone 1 | K5: =G5&"+"&H5 -> 1+0 | L5: =VLOOKUP(A5,'ZONE 1 PREMIUM'!$A$3:$M$16,13,0) -> 5 | M5: =VLOOKUP(D5,DROPDOWN!B:C,2,0) -> 4 | N5: =VLOOKUP(K5,$AQ$3:$AR$12,2,0) -> X3:AP16 | O5: =INDEX(INDIRECT(N5),L5,M5) -> 17919.3 | Q5: ROW NO | R5: =IF(R4="1+0",S5,T5) -> 4 | S5: =VLOOKUP(S3,DROPDOWN!O15:Q27,2,0) -> 4 | T5: =VLOOKUP(S3,DROPDOWN!O15:Q27,3,0) -> 2 | U5: =VLOOKUP(S2,DROPDOWN!O15:Q27,2,0) -> 4 | V5: =VLOOKUP(S1,DROPDOWN!O15:Q27,2,0) -> 4 | X5: 05-17 | Y5: 4068.7 | Z5: 4867.95 | AA5: 5817.85 | AB5: 6346.85 | AC5: 6833.3 | AD5: 7974.1 | AE5: 8687.1 | AF5: 9294.3 | AG5: 10374.15 | AH5: 12886.9 | AI5: 21072.6 | AJ5: 26569.6 | AK5: 32718.65 | AL5: 43824.2 | AM5: 53201.3 | AN5: 63567.4 | AO5: 75578 | AP5: 103210.2 | AQ5: 1+2 | AR5: X35:AP46 | AU5: 05-17 | AV5: 3615.75 | AW5: 4324.5 | AX5: 5164.875 | AY5: 5632.875 | AZ5: 6063.75 | BA5: 7075.125 | BB5: 7705.125 | BC5: 8242.875 | BD5: 9199.125 | BE5: 11424.375 | BF5: 18673.875 | BG5: 23540.625 | BH5: 28986.75 | BI5: 39103.875 | BJ5: 47407.5 | BK5: 56586.375 | BL5: 67222.125 | BM5: 91692 | BN5: 1+2 | BO5: AU35:BM46 | BR5: 05-17 | BS5: 3339.6 | BT5: 3991.9 | BU5: 4766.3 | BV5: 5197.5 | BW5: 5594.6 | BX5: 6526.3 | BY5: 7108.2 | BZ5: 7603.2 | CA5: 8484.3 | CB5: 10534.7 | CC5: 17215 | CD5: 21700.8 | CE5: 26717.9 | CF5: 36191.1 | CG5: 43842.7 | CH5: 52301.7 | CI5: 62102.7 | CJ5: 84652.7 | CK5: 1+2 | CL5: BR35:CJ46 | CO5: 05-17 | CP5: 3077.07 | CQ5: 3677.66 | CR5: 4389.43 | CS5: 4786.19 | CT5: 5151.34 | CU5: 6008.08 | CV5: 6542.18 | CW5: 6997.8 | CX5: 7808.76 | CY5: 9694.46 | CZ5: 15836.61 | DA5: 19961.17 | DB5: 24575.14 | DC5: 33436.84 | DD5: 40472.79 | DE5: 48251.03 | DF5: 57263.15 | DG5: 77997.13 | DH5: 1+1 | DI5: CO20:DG31
A6: 36-40 | B6: 36 Years | C6: 40 Years | D6: 5 | E6: INDIVIDUAL | F6: 1 | G6: 1 | H6: 0 | I6: 1 | J6: Zone 1 | K6: =G6&"+"&H6 -> 1+0 | L6: =VLOOKUP(A6,'ZONE 1 PREMIUM'!$A$3:$M$16,13,0) -> 6 | M6: =VLOOKUP(D6,DROPDOWN!B:C,2,0) -> 4 | N6: =VLOOKUP(K6,$AQ$3:$AR$12,2,0) -> X3:AP16 | O6: =INDEX(INDIRECT(N6),L6,M6) -> 20648.25 | Q6: COLUMN NO | R6: =VLOOKUP('CALCULATOR CARE V6'!B6,DROPDOWN!A:C,3,0) -> 19 | X6: 18-24 | Y6: 10297.1 | Z6: 12675.3 | AA6: 15584.8 | AB6: 17001.6 | AC6: 18303.4 | AD6: 21542.95 | AE6: 23710.7 | AF6: 25618.55 | AG6: 28574.05 | AH6: 35452.2 | AI6: 74110.6 | AJ6: 88767.35 | AK6: 105253.75 | AL6: 146358.2 | AM6: 173886.9 | AN6: 204381.45 | AO6: 239773.85 | AP6: 321052.4 | AQ6: 1+3 | AR6: X50:AP61 | AU6: 18-24 | AV6: 9137.25 | AW6: 11242.125 | AX6: 13834.125 | AY6: 15088.5 | AZ6: 16240.5 | BA6: 19123.875 | BB6: 21044.25 | BC6: 22734 | BD6: 25349.625 | BE6: 31440.375 | BF6: 65674.125 | BG6: 78654.375 | BH6: 93253.5 | BI6: 129713.62 | BJ6: 154091.25 | BK6: 181095.75 | BL6: 212436 | BM6: 284410.12 | BN6: 1+3 | BO6: AU50:BM61 | BR6: 18-24 | BS6: 8429.3 | BT6: 10369.7 | BU6: 12765.5 | BV6: 13921.6 | BW6: 14983.1 | BX6: 17648.4 | BY6: 19417.2 | BZ6: 20974.8 | CA6: 23386 | CB6: 28998.2 | CC6: 60545.1 | CD6: 72505.4 | CE6: 85959.5 | CF6: 119590.9 | CG6: 142055.1 | CH6: 166940.4 | CI6: 195820.9 | CJ6: 262146.5 | CK6: 1+3 | CL6: BR50:CJ61 | CO6: 18-24 | CP6: 7760.8 | CQ6: 9545.13 | CR6: 11755.65 | CS6: 12818.4 | CT6: 13795.04 | CU6: 16252.99 | CV6: 17880.36 | CW6: 19311.53 | CX6: 21528.59 | CY6: 26689.74 | CZ6: 55697.91 | DA6: 66696.01 | DB6: 79066.42 | DC6: 110024.6 | DD6: 130681.19 | DE6: 153563.56 | DF6: 180120.32 | DG6: 241109.09 | DH6: 1+2 | DI6: CO35:DG46
A7: 41-45 | B7: 41 Years | C7: 45 Years | D7: 5 | E7: INDIVIDUAL | F7: 1 | G7: 1 | H7: 0 | I7: 1 | J7: Zone 1 | K7: =G7&"+"&H7 -> 1+0 | L7: =VLOOKUP(A7,'ZONE 1 PREMIUM'!$A$3:$M$16,13,0) -> 7 | M7: =VLOOKUP(D7,DROPDOWN!B:C,2,0) -> 4 | N7: =VLOOKUP(K7,$AQ$3:$AR$12,2,0) -> X3:AP16 | O7: =INDEX(INDIRECT(N7),L7,M7) -> 23997.05 | Q7: APPLICABLE ARRAY | R7: =HLOOKUP(R8,S7:V8,2,0) -> CO3:DG16 | S7: ZONE 1 | T7: ZONE 1A | U7: ZONE 2 | V7: ZONE 3 | X7: 25-35 | Y7: 12023.25 | Z7: 14494.6 | AA7: 17919.3 | AB7: 19554.6 | AC7: 21061.1 | AD7: 24835.4 | AE7: 27181.4 | AF7: 29242.2 | AG7: 32623.2 | AH7: 40468.5 | AI7: 83744.15 | AJ7: 101433.45 | AK7: 121762 | AL7: 164939.9 | AM7: 197145.65 | AN7: 232939.4 | AO7: 274569.4 | AP7: 370004.45 | AQ7: 1+4 | AR7: X65:AP76 | AU7: 25-35 | AV7: 10672.875 | AW7: 12861 | AX7: 15914.25 | AY7: 17362.125 | AZ7: 18695.25 | BA7: 22059 | BB7: 24135.75 | BC7: 25961.625 | BD7: 28955.25 | BE7: 35902.125 | BF7: 74224.125 | BG7: 89888.625 | BH7: 107890.88 | BI7: 146211.75 | BJ7: 174730.5 | BK7: 206427.38 | BL7: 243292.5 | BM7: 327802.5 | BN7: 1+4 | BO7: AU65:BM76 | BR7: 25-35 | BS7: 9848.3 | BT7: 11865.7 | BU7: 14689.4 | BV7: 16023.7 | BW7: 17252.4 | BX7: 20363.2 | BY7: 22276.1 | BZ7: 23959.1 | CA7: 26717.9 | CB7: 33119.9 | CC7: 68434.3 | CD7: 82869.6 | CE7: 99457.6 | CF7: 134818.2 | CG7: 161098.3 | CH7: 190307.7 | CI7: 224279 | CJ7: 302156.8 | CK7: 1+4 | CL7: BR65:CJ76 | CO7: 25-35 | CP7: 9068.8 | CQ7: 10923.98 | CR7: 13531.26 | CS7: 14758.6 | CT7: 15888.93 | CU7: 18758.9 | CV7: 20519.25 | CW7: 22065.96 | CX7: 24603.48 | CY7: 30489.48 | CZ7: 62962.76 | DA7: 76235.69 | DB7: 91489.15 | DC7: 124049.63 | DD7: 148214.93 | DE7: 175073.62 | DF7: 206311.93 | DG7: 277921.66 | DH7: 1+3 | DI7: CO50:DG61
A8: 46-50 | B8: 46 Years | C8: 50 Years | D8: 5 | E8: INDIVIDUAL | F8: 1 | G8: 1 | H8: 0 | I8: 1 | J8: Zone 1 | K8: =G8&"+"&H8 -> 1+0 | L8: =VLOOKUP(A8,'ZONE 1 PREMIUM'!$A$3:$M$16,13,0) -> 8 | M8: =VLOOKUP(D8,DROPDOWN!B:C,2,0) -> 4 | N8: =VLOOKUP(K8,$AQ$3:$AR$12,2,0) -> X3:AP16 | O8: =INDEX(INDIRECT(N8),L8,M8) -> 29750.5 | Q8: ZONE | R8: ='CALCULATOR CARE V6'!B8 -> ZONE 3 | S8: =VLOOKUP(R4,AQ2:AR12,2,0) -> X3:AP16 | T8: =VLOOKUP(R4,BN3:BO12,2,0) -> AU3:BM16 | U8: =VLOOKUP(R4,CK2:CL12,2,0) -> BR3:CJ16 | V8: =VLOOKUP(R4,DH4:DI13,2,0) -> CO3:DG16 | X8: 36-40 | Y8: 13796.55 | Z8: 16666.95 | AA8: 20648.25 | AB8: 22563 | AC8: 24330.55 | AD8: 28695.95 | AE8: 31413.4 | AF8: 33800.8 | AG8: 37761.4 | AH8: 46916.55 | AI8: 87420.7 | AJ8: 108177.05 | AK8: 132074.05 | AL8: 171404.05 | AM8: 208124.7 | AN8: 249102.65 | AO8: 296882.85 | AP8: 406216.8 | AQ8: 2+0 | AR8: X81:AP92 | AU8: 36-40 | AV8: 12242.25 | AW8: 14784.75 | AX8: 18330.75 | AY8: 20026.125 | AZ8: 21592.125 | BA8: 25476.75 | BB8: 27883.125 | BC8: 29998.125 | BD8: 33504.75 | BE8: 41612.625 | BF8: 77479.875 | BG8: 95860.125 | BH8: 117021.38 | BI8: 151935.75 | BJ8: 184453.88 | BK8: 220740.75 | BL8: 263050.88 | BM8: 359870.62 | BN8: 2+0 | BO8: AU81:BM92 | BR8: 36-40 | BS8: 11294.8 | BT8: 13637.8 | BU8: 16915.8 | BV8: 18478.9 | BW8: 19921 | BX8: 23512.5 | BY8: 25730.1 | BZ8: 27678.2 | CA8: 30910 | CB8: 38381.2 | CC8: 71434 | CD8: 88371.8 | CE8: 107872.6 | CF8: 140092.7 | CG8: 170057.8 | CH8: 203496.7 | CI8: 242487.3 | CJ8: 331708.3 | CK8: 2+0 | CL8: BR81:CJ92 | CO8: 36-40 | CP8: 10399.69 | CQ8: 12553.53 | CR8: 15579.37 | CS8: 17015.99 | CT8: 18342.52 | CU8: 21655.03 | CV8: 23694.42 | CW8: 25486.38 | CX8: 28457.72 | CY8: 35327.99 | CZ8: 65720.46 | DA8: 81295.47 | DB8: 99227.06 | DC8: 128900.13 | DD8: 156454.24 | DE8: 187202.05 | DF8: 223054.33 | DG8: 305095.36 | DH8: 1+4 | DI8: CO65:DG76
A9: 51-55 | B9: 51 Years | C9: 55 Years | D9: 5 | E9: INDIVIDUAL | F9: 1 | G9: 1 | H9: 0 | I9: 1 | J9: Zone 1 | K9: =G9&"+"&H9 -> 1+0 | L9: =VLOOKUP(A9,'ZONE 1 PREMIUM'!$A$3:$M$16,13,0) -> 9 | M9: =VLOOKUP(D9,DROPDOWN!B:C,2,0) -> 4 | N9: =VLOOKUP(K9,$AQ$3:$AR$12,2,0) -> X3:AP16 | O9: =INDEX(INDIRECT(N9),L9,M9) -> 39063.2 | X9: 41-45 | Y9: 15997.65 | Z9: 19361.4 | AA9: 23997.05 | AB9: 26256.8 | AC9: 28349.8 | AD9: 33442 | AE9: 36520.55 | AF9: 39175.9 | AG9: 43826.5 | AH9: 54534.15 | AI9: 98832.15 | AJ9: 123391.55 | AK9: 151704.55 | AL9: 185825.05 | AM9: 228186.45 | AN9: 275599.8 | AO9: 330998.75 | AP9: 457535.55 | AQ9: 2+1 | AR9: X98:AP109 | AU9: 41-45 | AV9: 14191.875 | AW9: 17170.875 | AX9: 21295.125 | AY9: 23297.625 | AZ9: 25150.5 | BA9: 29680.875 | BB9: 32405.625 | BC9: 34758 | BD9: 38875.5 | BE9: 48358.125 | BF9: 87584.625 | BG9: 109333.12 | BH9: 134404.88 | BI9: 164705.62 | BJ9: 202218.75 | BK9: 244204.88 | BL9: 293262.75 | BM9: 405313.88 | BN9: 2+1 | BO9: AU98:BM109 | BR9: 41-45 | BS9: 13092.2 | BT9: 15836.7 | BU9: 19648.2 | BV9: 21492.9 | BW9: 23200.1 | BX9: 27385.6 | BY9: 29898 | BZ9: 32065 | CA9: 35858.9 | CB9: 44597.3 | CC9: 80746.6 | CD9: 100787.5 | CE9: 123890.8 | CF9: 151860.5 | CG9: 186429.1 | CH9: 225120.5 | CI9: 270327.2 | CJ9: 373585.3 | CK9: 2+1 | CL9: BR98:CJ109 | CO9: 41-45 | CP9: 12052.13 | CQ9: 14575.48 | CR9: 18091.82 | CS9: 19787.86 | CT9: 21357.46 | CU9: 25217.15 | CV9: 27526.86 | CW9: 29519.38 | CX9: 33008.47 | CY9: 41043.95 | CZ9: 74283.5 | DA9: 92712.13 | DB9: 113956.23 | DC9: 139720.56 | DD9: 171507.14 | DE9: 207084.74 | DF9: 248654.07 | DG9: 343601.79 | DH9: 2+0 | DI9: CO81:DG92
A10: 56-60 | B10: 56 Years | C10: 60 Years | D10: 5 | E10: INDIVIDUAL | F10: 1 | G10: 1 | H10: 0 | I10: 1 | J10: Zone 1 | K10: =G10&"+"&H10 -> 1+0 | L10: =VLOOKUP(A10,'ZONE 1 PREMIUM'!$A$3:$M$16,13,0) -> 10 | M10: =VLOOKUP(D10,DROPDOWN!B:C,2,0) -> 4 | N10: =VLOOKUP(K10,$AQ$3:$AR$12,2,0) -> X3:AP16 | O10: =INDEX(INDIRECT(N10),L10,M10) -> 52811.45 | Q10: BASE PREMIUM | R10: =INDEX(INDIRECT(R7),R5,R6) -> 241109.09 | S10: =INDEX(INDIRECT(R7),T2,R6) -> 241109.09 | T10: =INDEX(INDIRECT(R7),T1,R6) -> 241109.09 | X10: 46-50 | Y10: 19736.3 | Z10: 23917.7 | AA10: 29750.5 | AB10: 32584.1 | AC10: 35214.15 | AD10: 41587.45 | AE10: 45460.65 | AF10: 48817.5 | AG10: 54664.1 | AH10: 68076.55 | AI10: 119073.3 | AJ10: 150173.9 | AK10: 186076.9 | AL10: 213205.4 | AM10: 265352.15 | AN10: 323932 | AO10: 392535.25 | AP10: 548950.2 | AQ10: 2+2 | AR10: X113:AP124 | AU10: 46-50 | AV10: 17509.5 | AW10: 21213 | AX10: 26403.75 | AY10: 28913.625 | AZ10: 31242.375 | BA10: 36912.375 | BB10: 40342.5 | BC10: 43314.75 | BD10: 48492 | BE10: 60368.625 | BF10: 105527.25 | BG10: 133068.38 | BH10: 164862 | BI10: 188995.5 | BJ10: 235174.5 | BK10: 287047.12 | BL10: 347798.25 | BM10: 486308.25 | BN10: 2+2 | BO10: AU113:BM124 | BR10: 46-50 | BS10: 16152.4 | BT10: 19564.6 | BU10: 24362.8 | BV10: 26675 | BW10: 28821.1 | BX10: 34060.4 | BY10: 37220.7 | BZ10: 39960.8 | CA10: 44731.5 | CB10: 55675.4 | CC10: 97290.6 | CD10: 122669.8 | CE10: 151968.3 | CF10: 174266.4 | CG10: 216821 | CH10: 264622.6 | CI10: 320606 | CJ10: 448245.6 | CK10: 2+2 | CL10: BR113:CJ124 | CO10: 46-50 | CP10: 14869.78 | CQ10: 18007.89 | CR10: 22433.29 | CS10: 24559.88 | CT10: 26532.78 | CU10: 31364.75 | CV10: 34270.69 | CW10: 36789.68 | CX10: 41176.93 | CY10: 51240.9 | CZ10: 89506.44 | DA10: 112843.34 | DB10: 139783.78 | DC10: 160346.63 | DD10: 199476.54 | DE10: 243431.88 | DF10: 294910.4 | DG10: 412278.33 | DH10: 2+1 | DI10: CO98:DG109
A11: 61-65 | B11: 61 Years | C11: 65 Years | D11: 5 | E11: INDIVIDUAL | F11: 1 | G11: 1 | H11: 0 | I11: 1 | J11: Zone 1 | K11: =G11&"+"&H11 -> 1+0 | L11: =VLOOKUP(A11,'ZONE 1 PREMIUM'!$A$3:$M$16,13,0) -> 11 | M11: =VLOOKUP(D11,DROPDOWN!B:C,2,0) -> 4 | N11: =VLOOKUP(K11,$AQ$3:$AR$12,2,0) -> X3:AP16 | O11: =INDEX(INDIRECT(N11),L11,M11) -> 72870.9 | R11: =IF('CALCULATOR CARE V6'!B7='CARE SENIOR'!AP12,'CARE SENIOR'!AQ12,'CARE SHEET'!R10)*'CALCULATOR CARE V6'!N3 -> 186859.54 | S11: =IF('CALCULATOR CARE V6'!B2<=45,'optional benefits'!B7,'optional benefits'!B8) -> Less than or equal to 45 years | T11: =IF('CALCULATOR CARE V6'!E2<=45,'optional benefits'!B7,'optional benefits'!B8) -> Less than or equal to 45 years | U11: =IF('CALCULATOR CARE V6'!F2<=45,'optional benefits'!B7,'optional benefits'!B8) -> Less than or equal to 45 years | X11: 51-55 | Y11: 25847.4 | Z11: 31391.55 | AA11: 39063.2 | AB11: 42850.15 | AC11: 46374.9 | AD11: 54760.7 | AE11: 59958.7 | AF11: 64483.95 | AG11: 72322.35 | AH11: 90237.05 | AI11: 167150.2 | AJ11: 209187.3 | AK11: 257778.25 | AL11: 283550.9 | AM11: 353568.65 | AN11: 432395.4 | AO11: 524864.6 | AP11: 735313.45 | AQ11: 2+3 | AR11: X128:AP139 | AU11: 51-55 | AV11: 22920.75 | AW11: 27831.375 | AX11: 34650 | AY11: 38003.625 | AZ11: 41125.5 | BA11: 48577.5 | BB11: 53179.875 | BC11: 57187.125 | BD11: 64128.375 | BE11: 79993.125 | BF11: 148101.75 | BG11: 185326.88 | BH11: 228355.88 | BI11: 251309.25 | BJ11: 313311.38 | BK11: 383115.38 | BL11: 464999.62 | BM11: 651358.12 | BN11: 2+3 | BO11: AU128:BM139 | BR11: 51-55 | BS11: 21139.8 | BT11: 25664.1 | BU11: 31961.6 | BV11: 35051.5 | BW11: 37928 | BX11: 44809.6 | BY11: 49051.2 | BZ11: 52743.9 | CA11: 59140.4 | CB11: 73759.4 | CC11: 136523.2 | CD11: 170826.7 | CE11: 210478.4 | CF11: 231699.6 | CG11: 288836.9 | CH11: 353161.6 | CI11: 428620.5 | CJ11: 600352.5 | CK11: 2+3 | CL11: BR128:CJ139 | CO11: 51-55 | CP11: 19455.41 | CQ11: 23615.94 | CR11: 29421.28 | CS11: 32262.91 | CT11: 34907.25 | CU11: 41248.87 | CV11: 45148.89 | CW11: 48545.33 | CX11: 54425.88 | CY11: 67868.85 | CZ11: 125582.17 | DA11: 157124.59 | DB11: 193586.18 | DC11: 213169.12 | DD11: 265707.12 | DE11: 324855.97 | DF11: 394242.1 | DG11: 552154.76 | DH11: 2+2 | DI11: CO113:DG124
A12: 66-70 | B12: 66 Years | C12: 70 Years | D12: 5 | E12: INDIVIDUAL | F12: 1 | G12: 1 | H12: 0 | I12: 1 | J12: Zone 1 | K12: =G12&"+"&H12 -> 1+0 | L12: =VLOOKUP(A12,'ZONE 1 PREMIUM'!$A$3:$M$16,13,0) -> 12 | M12: =VLOOKUP(D12,DROPDOWN!B:C,2,0) -> 4 | N12: =VLOOKUP(K12,$AQ$3:$AR$12,2,0) -> X3:AP16 | O12: =INDEX(INDIRECT(N12),L12,M12) -> 92842.95 | Q12: Ncb-super | R12: =INDEX('optional benefits'!C7:P8,MATCH('CARE SHEET'!S11,'optional benefits'!B7:B8,0),MATCH('CALCULATOR CARE V6'!B6,'optional benefits'!C6:P6,0)) -> #N/A | S12: =IF('CALCULATOR CARE V6'!B12="YES",1+'CARE SHEET'!R12,1) -> 1 | T12: =IF('CALCULATOR CARE V6'!B12="YES",1+INDEX('optional benefits'!C7:P8,MATCH('CARE SHEET'!T11,'optional benefits'!B7:B8,0),MATCH('CALCULATOR CARE V6'!B6,'optional benefits'!C6:P6,0)),1) -> 1 | U12: =IF('CALCULATOR CARE V6'!B12="YES",1+INDEX('optional benefits'!C7:P8,MATCH('CARE SHEET'!U11,'optional benefits'!B7:B8,0),MATCH('CALCULATOR CARE V6'!B6,'optional benefits'!C6:P6,0)),1) -> 1 | X12: 56-60 | Y12: 34827.75 | Z12: 42355.65 | AA12: 52811.45 | AB12: 57992.2 | AC12: 62829.1 | AD12: 74262.4 | AE12: 81402.75 | AF12: 86599.6 | AG12: 97227.9 | AH12: 121431.95 | AI12: 223332.3 | AJ12: 280053.75 | AK12: 345761.3 | AL12: 382320.95 | AM12: 477404.1 | AN12: 584669.2 | AO12: 710700 | AP12: 997012.05 | AQ12: 2+4 | AR12: X143:AP154 | AU12: 56-60 | AV12: 30884.625 | AW12: 37551.375 | AX12: 46845 | AY12: 51432.75 | AZ12: 55715.625 | BA12: 65874.375 | BB12: 72198 | BC12: 76799.25 | BD12: 86212.125 | BE12: 107645.62 | BF12: 197880.75 | BG12: 248109.75 | BH12: 306295.88 | BI12: 338837.62 | BJ12: 423037.12 | BK12: 518024.25 | BL12: 629627.62 | BM12: 883165.5 | BN12: 2+4 | BO12: AU143:BM154 | BR12: 56-60 | BS12: 28484.5 | BT12: 34626.9 | BU12: 43209.1 | BV12: 47437.5 | BW12: 51384.3 | BX12: 60765.1 | BY12: 66591.8 | BZ12: 70832.3 | CA12: 79505.8 | CB12: 99257.4 | CC12: 182410.8 | CD12: 228697.7 | CE12: 282317.2 | CF12: 312393.4 | CG12: 389985.2 | CH12: 477517.7 | CI12: 580362.2 | CJ12: 814002.2 | CK12: 2+4 | CL12: BR143:CJ154 | CO12: 56-60 | CP12: 26215.59 | CQ12: 31863.97 | CR12: 39774.1 | CS12: 43662.13 | CT12: 47290.74 | CU12: 55935.53 | CV12: 61292.88 | CW12: 65191.81 | CX12: 73168.43 | CY12: 91330.01 | CZ12: 167791.33 | DA12: 210353.65 | DB12: 259657.62 | DC12: 287403.57 | DD12: 358750.61 | DE12: 439239.48 | DF12: 533806.79 | DG12: 748644.7 | DH12: 2+3 | DI12: CO128:DG139
A13: 71-75 | B13: 71 Years | C13: 75 Years | D13: 5 | E13: INDIVIDUAL | F13: 1 | G13: 1 | H13: 0 | I13: 1 | J13: Zone 1 | K13: =G13&"+"&H13 -> 1+0 | L13: =VLOOKUP(A13,'ZONE 1 PREMIUM'!$A$3:$M$16,13,0) -> 13 | M13: =VLOOKUP(D13,DROPDOWN!B:C,2,0) -> 4 | N13: =VLOOKUP(K13,$AQ$3:$AR$12,2,0) -> X3:AP16 | O13: =INDEX(INDIRECT(N13),L13,M13) -> 111223.4 | Q13: Smart select | R13: =15% -> 0.15 | S13: =IF('CALCULATOR CARE V6'!B13="YES",1-'CARE SHEET'!R13,1) -> 1 | X13: 61-65 | Y13: 47927.4 | Z13: 58408.5 | AA13: 72870.9 | AB13: 80142.35 | AC13: 86946.9 | AD13: 102776.65 | AE13: 112839.15 | AF13: 119781.7 | AG13: 134693.75 | AH13: 168524.45 | AI13: 306799.3 | AJ13: 385914.7 | AK13: 477765.2 | AL13: 531930.2 | AM13: 665515.35 | AN13: 816535.65 | AO13: 994261.25 | AP13: 1397293.7 | AU13: 61-65 | AV13: 42484.5 | AW13: 51765.75 | AX13: 64607.625 | AY13: 71047.125 | AZ13: 77072.625 | BA13: 91125 | BB13: 100036.12 | BC13: 106184.25 | BD13: 119388.38 | BE13: 149347.12 | BF13: 271793.25 | BG13: 341852.62 | BH13: 423189 | BI13: 471322.12 | BJ13: 589614.75 | BK13: 723348 | BL13: 880729.88 | BM13: 1237627.1 | BR13: 61-65 | BS13: 39173.2 | BT13: 47725.7 | BU13: 59578.2 | BV13: 65512.7 | BW13: 71065.5 | BX13: 84033.4 | BY13: 92244.9 | BZ13: 97909.9 | CA13: 110078.1 | CB13: 137685.9 | CC13: 250521.7 | CD13: 315084 | CE13: 390035.8 | CF13: 434480.2 | CG13: 543490.2 | CH13: 666727.6 | CI13: 811757.1 | CJ13: 1140645 | CO13: 61-65 | CP13: 36044.12 | CQ13: 43908.47 | CR13: 54825.91 | CS13: 60282.45 | CT13: 65388.01 | CU13: 77331.14 | CV13: 84881.57 | CW13: 90091.77 | CX13: 101280.62 | CY13: 126666.72 | CZ13: 230421.64 | DA13: 289787.4 | DB13: 358708.1 | DC13: 399665.94 | DD13: 499902.34 | DE13: 613222.01 | DF13: 746581.33 | DG13: 1049001.8 | DH13: 2+4 | DI13: CO143:DG154
A14: 75+ | B14: >75 Years | D14: 5 | E14: INDIVIDUAL | F14: 1 | G14: 1 | H14: 0 | I14: 1 | J14: Zone 1 | K14: =G14&"+"&H14 -> 1+0 | L14: =VLOOKUP(A14,'ZONE 1 PREMIUM'!$A$3:$M$16,13,0) -> 14 | M14: =VLOOKUP(D14,DROPDOWN!B:C,2,0) -> 4 | N14: =VLOOKUP(K14,$AQ$3:$AR$12,2,0) -> X3:AP16 | O14: =INDEX(INDIRECT(N14),L14,M14) -> 148912.35 | Q14: Reduction in PED | R14: =VLOOKUP(T14,'optional benefits'!B51:C54,2,0) -> 0.15 | S14: =IF('CALCULATOR CARE V6'!B14="YES",1+'CARE SHEET'!R14,1) -> 1 | T14: =VLOOKUP(S3,DROPDOWN!L20:M110,2,0) -> Upto 45 Years | U14: =IF('CALCULATOR CARE V6'!B14="YES",1+VLOOKUP(U2,'optional benefits'!B51:C54,2,0),1) -> 1 | V14: =IF('CALCULATOR CARE V6'!B14="YES",1+VLOOKUP(U3,'optional benefits'!B51:C54,2,0),1) -> 1 | X14: 66-70 | Y14: 60881 | Z14: 74322.2 | AA14: 92842.95 | AB14: 102241.9 | AC14: 111062.4 | AD14: 131342.65 | AE14: 144449.2 | AF14: 155968.75 | AG14: 175617.65 | AH14: 220032.95 | AI14: 389046.15 | AJ14: 492315 | AK14: 612501.5 | AL14: 695669.5 | AM14: 871932.3 | AN14: 1071630.9 | AO14: 1307027.9 | AP14: 1839893 | AU14: 66-70 | AV14: 53958.375 | AW14: 65859.75 | AX14: 82296 | AY14: 90619.875 | AZ14: 98429.625 | BA14: 116422.88 | BB14: 128034 | BC14: 138234.38 | BD14: 155633.62 | BE14: 194964.75 | BF14: 344640.38 | BG14: 436087.12 | BH14: 542515.5 | BI14: 616317.75 | BJ14: 772403.62 | BK14: 949242.38 | BL14: 1157693.6 | BM14: 1629561.4 | BR14: 66-70 | BS14: 49747.5 | BT14: 60715.6 | BU14: 75880.2 | BV14: 83550.5 | BW14: 90747.8 | BX14: 107346.8 | BY14: 118048.7 | BZ14: 127449.3 | CA14: 143482.9 | CB14: 179726.8 | CC14: 317659.1 | CD14: 401930.1 | CE14: 500006.1 | CF14: 568097.2 | CG14: 711933.2 | CH14: 874892.7 | CI14: 1066985.7 | CJ14: 1501820.1 | CO14: 66-70 | CP14: 45769.1 | CQ14: 55853.78 | CR14: 69816.68 | CS14: 76870.07 | CT14: 83487.46 | CU14: 98770.35 | CV14: 108611.96 | CW14: 117256.75 | CX14: 132000.09 | CY14: 165327.93 | CZ14: 292163.6 | DA14: 369652.79 | DB14: 459836.12 | DC14: 522529.65 | DD14: 654790.25 | DE14: 804635.82 | DF14: 981269.23 | DG14: 1381110.7
A15: 18-24 | B15: 18 Years | C15: 24 Years | D15: 5 | E15: FLOATER | F15: 2 | G15: 1 | H15: 1 | I15: 1 | J15: Zone 1 | K15: =G15&"+"&H15 -> 1+1 | L15: =VLOOKUP(A15,'ZONE 1 PREMIUM'!$A$4:$N$16,14,0) -> 2 | M15: =VLOOKUP(D15,DROPDOWN!B:C,2,0) -> 4 | N15: =VLOOKUP(K15,$AQ$3:$AR$12,2,0) -> X20:AP31 | O15: =INDEX(INDIRECT(N15),L15,M15) -> 16951 | Q15: Room Rent modification | R15: =IF(T3<5,'optional benefits'!C87,'optional benefits'!C88) -> 0.125 | S15: =IF('CALCULATOR CARE V6'!B15="YES",1+'CARE SHEET'!R15,1) -> 1 | V15: CARE SHIELD | X15: 71-75 | Y15: 72692.65 | Z15: 88885.8 | AA15: 111223.4 | AB15: 122636 | AC15: 133374.7 | AD15: 157846.7 | AE15: 173817.9 | AF15: 187923.8 | AG15: 211866.8 | AH15: 265792.6 | AI15: 455161.95 | AJ15: 579790.9 | AK15: 725204.95 | AL15: 842438.25 | AM15: 1057553.8 | AN15: 1301772.4 | AO15: 1590109.6 | AP15: 2241659.3 | AU15: 71-75 | AV15: 64417.5 | AW15: 78756.75 | AX15: 98572.5 | AY15: 108679.5 | AZ15: 118188 | BA15: 139893.75 | BB15: 154040.62 | BC15: 166532.62 | BD15: 187734.38 | BE15: 235487.25 | BF15: 403187.62 | BG15: 513550.12 | BH15: 642318.75 | BI15: 746286.75 | BJ15: 936777.38 | BK15: 1153039.5 | BL15: 1408371.8 | BM15: 1985338.1 | BR15: 71-75 | BS15: 59386.8 | BT15: 72600 | BU15: 90878.7 | BV15: 100192.4 | BW15: 108955 | BX15: 128976.1 | BY15: 142014.4 | BZ15: 153525.9 | CA15: 173064.1 | CB15: 217069.6 | CC15: 371611.9 | CD15: 473313.5 | CE15: 591976 | CF15: 687865.2 | CG15: 863405.4 | CH15: 1062695.7 | CI15: 1297989 | CJ15: 1829675.1 | CO15: 71-75 | CP15: 54631.89 | CQ15: 66782.12 | CR15: 83608.45 | CS15: 92172.58 | CT15: 100230.95 | CU15: 118658.49 | CV15: 130649.58 | CW15: 141234.57 | CX15: 159199.95 | CY15: 199664.02 | CZ15: 341774.95 | DA15: 435291.5 | DB15: 544404.86 | DC15: 632658.89 | DD15: 794073.72 | DE15: 977325.61 | DF15: 1193683 | DG15: 1682581.8
A16: 25-35 | B16: 25 Years | C16: 35 Years | D16: 5 | E16: FLOATER | F16: 2 | G16: 1 | H16: 1 | I16: 1 | J16: Zone 1 | K16: =G16&"+"&H16 -> 1+1 | L16: =VLOOKUP(A16,'ZONE 1 PREMIUM'!$A$4:$N$16,14,0) -> 3 | M16: =VLOOKUP(D16,DROPDOWN!B:C,2,0) -> 4 | N16: =VLOOKUP(K16,$AQ$3:$AR$12,2,0) -> X20:AP31 | O16: =INDEX(INDIRECT(N16),L16,M16) -> 18759.95 | Q16: Unlimited recharge | R16: =INDEX('optional benefits'!C14:P15,MATCH('CARE SHEET'!S11,'optional benefits'!B14:B15,0),MATCH('CALCULATOR CARE V6'!B6,'optional benefits'!C13:P13,0)) -> #N/A | S16: =IF('CALCULATOR CARE V6'!B16="YES",1+'CARE SHEET'!R16,1) -> 1 | T16: =IF('CALCULATOR CARE V6'!B16="YES",1+INDEX('optional benefits'!C14:P15,MATCH('CARE SHEET'!T11,'optional benefits'!B14:B15,0),MATCH('CALCULATOR CARE V6'!B6,'optional benefits'!C13:P13,0)),1) -> 1 | U16: =IF('CALCULATOR CARE V6'!B16="YES",1+INDEX('optional benefits'!C14:P15,MATCH('CARE SHEET'!U11,'optional benefits'!B14:B15,0),MATCH('CALCULATOR CARE V6'!B6,'optional benefits'!C13:P13,0)),1) -> 1 | V16: 0.085 | X16: 75+ | Y16: 97080.7 | Z16: 118895.05 | AA16: 148912.35 | AB16: 164409.75 | AC16: 179030.85 | AD16: 212022.05 | AE16: 233781.2 | AF16: 253096.6 | AG16: 285723.25 | AH16: 358940.3 | AI16: 593725.45 | AJ16: 761879.6 | AK16: 958587.1 | AL16: 1140764.3 | AM16: 1434366.2 | AN16: 1768372.2 | AO16: 2163347.8 | AP16: 3054293 | AU16: 75+ | AV16: 86013 | AW16: 105331.5 | AX16: 131947.88 | AY16: 145670.62 | AZ16: 158618.25 | BA16: 187867.12 | BB16: 207139.5 | BC16: 224244 | BD16: 253136.25 | BE16: 317972.25 | BF16: 525889.12 | BG16: 674794.12 | BH16: 848984.62 | BI16: 1010462.6 | BJ16: 1270455.8 | BK16: 1566228.4 | BL16: 1915990.9 | BM16: 2704948.9 | BR16: 75+ | BS16: 79286.9 | BT16: 97089.3 | BU16: 121634.7 | BV16: 134281.4 | BW16: 146212 | BX16: 173184 | BY16: 190946.8 | BZ16: 206708.7 | CA16: 233333.1 | CB16: 293080.7 | CC16: 484684.2 | CD16: 621903.7 | CE16: 782423.4 | CF16: 931308.4 | CG16: 1170898.3 | CH16: 1443457.4 | CI16: 1765769.5 | CJ16: 2492810.1 | CO16: 75+ | CP16: 72930.81 | CQ16: 89300.43 | CR16: 111889.59 | CS16: 123517.71 | CT16: 134488.56 | CU16: 159308.95 | CV16: 175643.69 | CW16: 190137.42 | CX16: 214618.82 | CY16: 269558.09 | CZ16: 445746.78 | DA16: 571924.09 | DB16: 719525.35 | DC16: 856511.1 | DD16: 1076819.7 | DE16: 1327445.6 | DF16: 1623819.9 | DG16: 2292351.8
A17: 36-40 | B17: 36 Years | C17: 40 Years | D17: 5 | E17: FLOATER | F17: 2 | G17: 1 | H17: 1 | I17: 1 | J17: Zone 1 | K17: =G17&"+"&H17 -> 1+1 | L17: =VLOOKUP(A17,'ZONE 1 PREMIUM'!$A$4:$N$16,14,0) -> 4 | M17: =VLOOKUP(D17,DROPDOWN!B:C,2,0) -> 4 | N17: =VLOOKUP(K17,$AQ$3:$AR$12,2,0) -> X20:AP31 | O17: =INDEX(INDIRECT(N17),L17,M17) -> 21637.25 | Q17: CO-PAYMENT | R17: =20% -> 0.2 | S17: =IF('CALCULATOR CARE V6'!B17="YES",1-'CARE SHEET'!R17,1) -> 0.8 | V17: =R11*S12*S17*S27 -> 149487.64 | Y17: q
A18: 41-45 | B18: 41 Years | C18: 45 Years | D18: 5 | E18: FLOATER | F18: 2 | G18: 1 | H18: 1 | I18: 1 | J18: Zone 1 | K18: =G18&"+"&H18 -> 1+1 | L18: =VLOOKUP(A18,'ZONE 1 PREMIUM'!$A$4:$N$16,14,0) -> 5 | M18: =VLOOKUP(D18,DROPDOWN!B:C,2,0) -> 4 | N18: =VLOOKUP(K18,$AQ$3:$AR$12,2,0) -> X20:AP31 | O18: =INDEX(INDIRECT(N18),L18,M18) -> 25416.15 | Q18: Everyday care | R18: =IF('CALCULATOR CARE V6'!B18="YES",INDEX('optional benefits'!B21:T30,MATCH('CARE SHEET'!R4,'optional benefits'!A21:A30,0),MATCH('CALCULATOR CARE V6'!B6,'optional benefits'!B20:T20,0)),0) -> 31906.687 | V18: =V17*V16 -> 12706.449 | X18: 1A1C | Y18: q
A19: 46-50 | B19: 46 Years | C19: 50 Years | D19: 5 | E19: FLOATER | F19: 2 | G19: 1 | H19: 1 | I19: 1 | J19: Zone 1 | K19: =G19&"+"&H19 -> 1+1 | L19: =VLOOKUP(A19,'ZONE 1 PREMIUM'!$A$4:$N$16,14,0) -> 6 | M19: =VLOOKUP(D19,DROPDOWN!B:C,2,0) -> 4 | N19: =VLOOKUP(K19,$AQ$3:$AR$12,2,0) -> X20:AP31 | O19: =INDEX(INDIRECT(N19),L19,M19) -> 30929.25 | Q19: Care Shield | R19: =IF('CALCULATOR CARE V6'!B19="YES",'CARE SHEET'!V18,0) -> 12706.449 | W19: add si | Y19: Care 3 | AA19: Care 4 | AD19: Care 5 | AI19: Care 6 | AL19: Care 7 | AT19: 1A1C | AV19: Care 3 | AX19: Care 4 | BA19: Care 5 | BF19: Care 6 | BI19: Care 7 | BQ19: 1A1C | BS19: Care 3 | BU19: Care 4 | BX19: Care 5 | CC19: Care 6 | CF19: Care 7 | CN19: 1A1C | CP19: Care 3 | CR19: Care 4 | CU19: Care 5 | CZ19: Care 6 | DC19: Care 7
A20: 51-55 | B20: 51 Years | C20: 55 Years | D20: 5 | E20: FLOATER | F20: 2 | G20: 1 | H20: 1 | I20: 1 | J20: Zone 1 | K20: =G20&"+"&H20 -> 1+1 | L20: =VLOOKUP(A20,'ZONE 1 PREMIUM'!$A$4:$N$16,14,0) -> 7 | M20: =VLOOKUP(D20,DROPDOWN!B:C,2,0) -> 4 | N20: =VLOOKUP(K20,$AQ$3:$AR$12,2,0) -> X20:AP31 | O20: =INDEX(INDIRECT(N20),L20,M20) -> 40040.7 | Q20: OPD Care | R20: =IF('CALCULATOR CARE V6'!B20="YES",INDEX('optional benefits'!C35:L44,MATCH('CARE SHEET'!R4,'optional benefits'!B35:B44,0),MATCH('CALCULATOR CARE V6'!C20,'optional benefits'!C34:L34,0)),0) -> 2285.3708 | V20: DA+ | W20: =VLOOKUP('CALCULATOR CARE V6'!C24,DROPDOWN!F5:G14,2,0) -> 1 | X20: Age-Band/ SI | Y20: 3L | Z20: 4L | AA20: 5L | AB20: 7L | AC20: 10L | AD20: 15L | AE20: 20L | AF20: 25L | AG20: 30L | AH20: 40L | AI20: 50L | AJ20: 60L | AK20: 75L | AL20: 1 CR | AM20: 1.5 CR | AN20: 2 CR | AO20: 3 CR | AP20: 6 CR | AU20: Age-Band/ SI | AV20: 3L | AW20: 4L | AX20: 5L | AY20: 7L | AZ20: 10L | BA20: 15L | BB20: 20L | BC20: 25L | BD20: 30L | BE20: 40L | BF20: 50L | BG20: 60L | BH20: 75L | BI20: 1 CR | BJ20: 1.5 CR | BK20: 2 CR | BL20: 3 CR | BM20: 6 CR | BR20: Age-Band/ SI | BS20: 3L | BT20: 4L | BU20: 5L | BV20: 7L | BW20: 10L | BX20: 15L | BY20: 20L | BZ20: 25L | CA20: 30L | CB20: 40L | CC20: 50L | CD20: 60L | CE20: 75L | CF20: 1 CR | CG20: 1.5 CR | CH20: 2 CR | CI20: 3 CR | CJ20: 6 CR | CO20: Age-Band/ SI | CP20: 3L | CQ20: 4L | CR20: 5L | CS20: 7L | CT20: 10L | CU20: 15L | CV20: 20L | CW20: 25L | CX20: 30L | CY20: 40L | CZ20: 50L | DA20: 60L | DB20: 75L | DC20: 1 CR | DD20: 1.5 CR | DE20: 2 CR | DF20: 3 CR | DG20: 6 CR
A21: 56-60 | B21: 56 Years | C21: 60 Years | D21: 5 | E21: FLOATER | F21: 2 | G21: 1 | H21: 1 | I21: 1 | J21: Zone 1 | K21: =G21&"+"&H21 -> 1+1 | L21: =VLOOKUP(A21,'ZONE 1 PREMIUM'!$A$4:$N$16,14,0) -> 8 | M21: =VLOOKUP(D21,DROPDOWN!B:C,2,0) -> 4 | N21: =VLOOKUP(K21,$AQ$3:$AR$12,2,0) -> X20:AP31 | O21: =INDEX(INDIRECT(N21),L21,M21) -> 54439.85 | Q21: Air Ambulance | R21: =IF('CALCULATOR CARE V6'!B21="YES",'optional benefits'!C59*'CARE SHEET'!S17*S27,0) -> 0 | U21: =VLOOKUP('CALCULATOR CARE V6'!H3,DROPDOWN!$K:$N,4,0) -> Upto 45 Years | V21: =IF('CALCULATOR CARE V6'!I3="YES",VLOOKUP(U21,'optional benefits'!$A$115:$C$118,2,0)*$W$20,0) -> 413.08982 | W21: =IF('CALCULATOR CARE V6'!I3="yes",INDEX('ADD SI'!$B$45:$AB$49,MATCH('CARE SHEET'!U21,'ADD SI'!$B$45:$B$49,0),MATCH('CARE SHEET'!$T$3,'ADD SI'!$B$45:$Q$45,0)),0) -> #N/A | X21: 18-24 | Y21: 11110.15 | Z21: 13517.1 | AA21: 16951 | AB21: 17891.7 | AC21: 19245.25 | AD21: 24315.6 | AE21: 26655.85 | AF21: 28694.8 | AG21: 31984.95 | AH21: 39652 | AI21: 76208.2 | AJ21: 92630.2 | AK21: 111071.6 | AL21: 162783.65 | AM21: 192907.9 | AN21: 226178.55 | AO21: 264723.1 | AP21: 353329.45 | AU21: 18-24 | AV21: 9869.625 | AW21: 12001.5 | AX21: 15058.125 | AY21: 15889.5 | AZ21: 17087.625 | BA21: 21592.125 | BB21: 23664.375 | BC21: 25470 | BD21: 28383.75 | BE21: 35173.125 | BF21: 67545 | BG21: 82086.75 | BH21: 98417.25 | BI21: 145074.38 | BJ21: 171749.25 | BK21: 201211.88 | BL21: 235343.25 | BM21: 313807.5 | BR21: 18-24 | BS21: 9111.3 | BT21: 11075.9 | BU21: 13900.7 | BV21: 14666.3 | BW21: 15770.7 | BX21: 19929.8 | BY21: 21839.4 | BZ21: 23502.6 | CA21: 26187.7 | CB21: 32444.5 | CC21: 62275.4 | CD21: 75676.7 | CE21: 90724.7 | CF21: 134174.7 | CG21: 158757.5 | CH21: 185906.6 | CI21: 217360 | CJ21: 289666.3 | CO21: 18-24 | CP21: 8395.18 | CQ21: 10201.31 | CR21: 12807.5 | CS21: 13510.55 | CT21: 14526.43 | CU21: 18357.78 | CV21: 20113.77 | CW21: 21644.13 | CX21: 24112.98 | CY21: 29866 | CZ21: 57295.85 | DA21: 69618.3 | DB21: 83455.85 | DC21: 123869.78 | DD21: 146473.11 | DE21: 171438.47 | DF21: 200360.53 | DG21: 266847.26
A22: 61-65 | B22: 61 Years | C22: 65 Years | D22: 5 | E22: FLOATER | F22: 2 | G22: 1 | H22: 1 | I22: 1 | J22: Zone 1 | K22: =G22&"+"&H22 -> 1+1 | L22: =VLOOKUP(A22,'ZONE 1 PREMIUM'!$A$4:$N$16,14,0) -> 9 | M22: =VLOOKUP(D22,DROPDOWN!B:C,2,0) -> 4 | N22: =VLOOKUP(K22,$AQ$3:$AR$12,2,0) -> X20:AP31 | O22: =INDEX(INDIRECT(N22),L22,M22) -> 73485 | Q22: BE-FIT | R22: =IF('CALCULATOR CARE V6'!B22="YES",'optional benefits'!C81*'CALCULATOR CARE V6'!K10,0) -> 0 | U22: =VLOOKUP('CALCULATOR CARE V6'!H4,DROPDOWN!$K:$N,4,0) -> Upto 45 Years | V22: =IF('CALCULATOR CARE V6'!I4="YES",VLOOKUP(U22,'optional benefits'!$A$115:$C$118,2,0)*$W$20,0) -> 0 | W22: =IF('CALCULATOR CARE V6'!I4="yes",INDEX('ADD SI'!$B$45:$AB$49,MATCH('CARE SHEET'!U22,'ADD SI'!$B$45:$B$49,0),MATCH('CARE SHEET'!$T$3,'ADD SI'!$B$45:$Q$45,0)),0) -> 0 | X22: 25-35 | Y22: 12390.1 | Z22: 14867.2 | AA22: 18759.95 | AB22: 19804.15 | AC22: 21307.2 | AD22: 26939.9 | AE22: 29420.45 | AF22: 31580.15 | AG22: 35203.8 | AH22: 43627.55 | AI22: 83941.95 | AJ22: 102738.7 | AK22: 124190.8 | AL22: 177019.5 | AM22: 210804.2 | AN22: 248230.95 | AO22: 291671.05 | AP22: 391385.25 | AU22: 25-35 | AV22: 11010.375 | AW22: 13204.125 | AX22: 16673.625 | AY22: 17596.125 | AZ22: 18927 | BA22: 23936.625 | BB22: 26131.5 | BC22: 28045.125 | BD22: 31253.625 | BE22: 38713.5 | BF22: 74413.125 | BG22: 91057.5 | BH22: 110054.25 | BI22: 157686.75 | BJ22: 187605 | BK22: 220746.38 | BL22: 259214.62 | BM22: 347514.75 | BR22: 25-35 | BS22: 10167.3 | BT22: 12188 | BU22: 15397.8 | BV22: 16247 | BW22: 17473.5 | BX22: 22099 | BY22: 24123 | BZ22: 25886.3 | CA22: 28843.1 | CB22: 35717 | CC22: 68614.7 | CD22: 83953.1 | CE22: 101458.5 | CF22: 145801.7 | CG22: 173372.1 | CH22: 203912.5 | CI22: 239362.2 | CJ22: 320731.4 | CO22: 25-35 | CP22: 9369.64 | CQ22: 11228.09 | CR22: 14190.71 | CS22: 14971.15 | CT22: 16098.21 | CU22: 20363.38 | CV22: 22224.01 | CW22: 23844.84 | CX22: 26564.39 | CY22: 32885.3 | CZ22: 63136.07 | DA22: 77239.58 | DB22: 93336.7 | DC22: 134564.86 | DD22: 159916.08 | DE22: 187998.84 | DF22: 220595.29 | DG22: 295416.16
A23: 66-70 | B23: 66 Years | C23: 70 Years | D23: 5 | E23: FLOATER | F23: 2 | G23: 1 | H23: 1 | I23: 1 | J23: Zone 1 | K23: =G23&"+"&H23 -> 1+1 | L23: =VLOOKUP(A23,'ZONE 1 PREMIUM'!$A$4:$N$16,14,0) -> 10 | M23: =VLOOKUP(D23,DROPDOWN!B:C,2,0) -> 4 | N23: =VLOOKUP(K23,$AQ$3:$AR$12,2,0) -> X20:AP31 | O23: =INDEX(INDIRECT(N23),L23,M23) -> 95891.6 | Q23: INTERNATIONAL SECOND OPINION | R23: =IF('CALCULATOR CARE V6'!B23="YES",'optional benefits'!C126,0) -> 0 | U23: =VLOOKUP('CALCULATOR CARE V6'!H5,DROPDOWN!$K:$N,4,0) -> Upto 45 Years | V23: =IF('CALCULATOR CARE V6'!I5="YES",VLOOKUP(U23,'optional benefits'!$A$115:$C$118,2,0)*$W$20,0) -> 0 | W23: =IF('CALCULATOR CARE V6'!I5="yes",INDEX('ADD SI'!$B$45:$AB$49,MATCH('CARE SHEET'!U23,'ADD SI'!$B$45:$B$49,0),MATCH('CARE SHEET'!$T$3,'ADD SI'!$B$45:$Q$45,0)),0) -> 0 | X23: 36-40 | Y23: 14143.85 | Z23: 17045.3 | AA23: 21637.25 | AB23: 22866.6 | AC23: 24628.4 | AD23: 31174.2 | AE23: 34083.7 | AF23: 36626.35 | AG23: 40872.15 | AH23: 50711.55 | AI23: 89686.2 | AJ23: 111702.95 | AK23: 136874.15 | AL23: 186281.6 | AM23: 225271.2 | AN23: 268631.95 | AO23: 319087.05 | AP23: 434709.2 | AU23: 36-40 | AV23: 12564 | AW23: 15133.5 | AX23: 19225.125 | AY23: 20311.875 | AZ23: 21871.125 | BA23: 27690.75 | BB23: 30268.125 | BC23: 32519.25 | BD23: 36279 | BE23: 44992.125 | BF23: 79504.875 | BG23: 99002.25 | BH23: 121291.88 | BI23: 165692.25 | BJ23: 200218.5 | BK23: 238615.88 | BL23: 283295.25 | BM23: 385681.5 | BR23: 36-40 | BS23: 11598.4 | BT23: 13966.7 | BU23: 17750.7 | BV23: 18750.6 | BW23: 20188.3 | BX23: 25562.9 | BY23: 27937.8 | BZ23: 30012.4 | CA23: 33477.4 | CB23: 41506.3 | CC23: 73310.6 | CD23: 91276.9 | CE23: 111818.3 | CF23: 153074.9 | CG23: 184891.3 | CH23: 220275 | CI23: 261448 | CJ23: 355799.4 | CO23: 36-40 | CP23: 10686.36 | CQ23: 12864.18 | CR23: 16356.54 | CS23: 17275.41 | CT23: 18596.49 | CU23: 23551.63 | CV23: 25734.9 | CW23: 27642.4 | CX23: 30828.47 | CY23: 38212.13 | CZ23: 67456.83 | DA23: 83976.87 | DB23: 102864.39 | DC23: 141147.37 | DD23: 170402.97 | DE23: 202939.47 | DF23: 240798.44 | DG23: 327556.99
A24: 71-75 | B24: 71 Years | C24: 75 Years | D24: 5 | E24: FLOATER | F24: 2 | G24: 1 | H24: 1 | I24: 1 | J24: Zone 1 | K24: =G24&"+"&H24 -> 1+1 | L24: =VLOOKUP(A24,'ZONE 1 PREMIUM'!$A$4:$N$16,14,0) -> 11 | M24: =VLOOKUP(D24,DROPDOWN!B:C,2,0) -> 4 | N24: =VLOOKUP(K24,$AQ$3:$AR$12,2,0) -> X20:AP31 | O24: =INDEX(INDIRECT($N$24),$L$24,$M$24) -> 112788.55 | Q24: Daily Allowance+ | R24: =IF('CALCULATOR CARE V6'!B24="YES",V41*S12*S14*S16,0) -> 0 | U24: =VLOOKUP('CALCULATOR CARE V6'!H6,DROPDOWN!$K:$N,4,0) -> Upto 45 Years | V24: =IF('CALCULATOR CARE V6'!I6="YES",VLOOKUP(U24,'optional benefits'!$A$115:$C$118,2,0)*$W$20,0) -> 0 | W24: =IF('CALCULATOR CARE V6'!I6="yes",INDEX('ADD SI'!$B$45:$AB$49,MATCH('CARE SHEET'!U24,'ADD SI'!$B$45:$B$49,0),MATCH('CARE SHEET'!$T$3,'ADD SI'!$B$45:$Q$45,0)),0) -> 0 | X24: 41-45 | Y24: 16495.6 | Z24: 19943.3 | AA24: 25416.15 | AB24: 26891.6 | AC24: 28992.65 | AD24: 36714.9 | AE24: 40097.05 | AF24: 43018.05 | AG24: 48057.35 | AH24: 59696.5 | AI24: 103625.35 | AJ24: 129909.75 | AK24: 160013.3 | AL24: 204763.25 | AM24: 250572.35 | AN24: 301684.1 | AO24: 361281.7 | AP24: 497629.15 | AU24: 41-45 | AV24: 14649.75 | AW24: 17701.875 | AX24: 22576.5 | AY24: 23880.375 | AZ24: 25742.25 | BA24: 32605.875 | BB24: 35599.5 | BC24: 38187 | BD24: 42649.875 | BE24: 52956 | BF24: 91857.375 | BG24: 115131.38 | BH24: 141789.38 | BI24: 181846.12 | BJ24: 222411.38 | BK24: 267672.38 | BL24: 320448.38 | BM24: 441187.88 | BR24: 41-45 | BS24: 13522.3 | BT24: 16335 | BU24: 20841.7 | BV24: 22041.8 | BW24: 23756.7 | BX24: 30096 | BY24: 32854.8 | BZ24: 35238.5 | CA24: 39351.4 | CB24: 48849.9 | CC24: 84696.7 | CD24: 106145.6 | CE24: 130710.8 | CF24: 167849 | CG24: 205231.4 | CH24: 246940.1 | CI24: 295574.4 | CJ24: 406838.3 | CO24: 41-45 | CP24: 12455.43 | CQ24: 15042 | CR24: 19201.44 | CS24: 20303.43 | CT24: 21880.66 | CU24: 27723.06 | CV24: 30260.58 | CW24: 32452.57 | CX24: 36234.87 | CY24: 44967.95 | CZ24: 77930.64 | DA24: 97653.1 | DB24: 120241.17 | DC24: 154619.77 | DD24: 188992.92 | DE24: 227345.66 | DF24: 272066.18 | DG24: 374375.76
A25: 75+ | B25: >75 Years | D25: 5 | E25: FLOATER | F25: 2 | G25: 1 | H25: 1 | I25: 1 | J25: Zone 1 | K25: =G25&"+"&H25 -> 1+1 | L25: =VLOOKUP(A25,'ZONE 1 PREMIUM'!$A$4:$N$16,14,0) -> 12 | M25: =VLOOKUP(D25,DROPDOWN!B:C,2,0) -> 4 | N25: =VLOOKUP(K25,$AQ$3:$AR$12,2,0) -> X20:AP31 | O25: =INDEX(INDIRECT(N25),L25,M25) -> 152572.8 | Q25: Advance Annual Health Check up | R25: =IF('CALCULATOR CARE V6'!B25="YES",'CARE SHEET'!V31,0) -> 0 | U25: =VLOOKUP('CALCULATOR CARE V6'!H7,DROPDOWN!$K:$N,4,0) -> Upto 45 Years | V25: =IF('CALCULATOR CARE V6'!I7="YES",VLOOKUP(U25,'optional benefits'!$A$115:$C$118,2,0)*$W$20,0) -> 0 | W25: =IF('CALCULATOR CARE V6'!I7="yes",INDEX('ADD SI'!$B$45:$AB$49,MATCH('CARE SHEET'!U25,'ADD SI'!$B$45:$B$49,0),MATCH('CARE SHEET'!$T$3,'ADD SI'!$B$45:$Q$45,0)),0) -> 0 | X25: 46-50 | Y25: 20020.35 | Z25: 24262.7 | AA25: 30929.25 | AB25: 34506.9 | AC25: 37243.9 | AD25: 45268.6 | AE25: 49499.45 | AF25: 53171.4 | AG25: 59457.3 | AH25: 73924.3 | AI25: 125191.3 | AJ25: 158191.7 | AK25: 196071.55 | AL25: 235547.6 | AM25: 291893 | AN25: 354983.15 | AO25: 428717.7 | AP25: 597114.5 | AU25: 46-50 | AV25: 17776.125 | AW25: 21534.75 | AX25: 27471.375 | AY25: 30637.125 | AZ25: 33061.5 | BA25: 40200.75 | BB25: 43947 | BC25: 47198.25 | BD25: 52764.75 | BE25: 65575.125 | BF25: 110974.5 | BG25: 140197.5 | BH25: 173740.5 | BI25: 208992.38 | BJ25: 258888.38 | BK25: 314757 | BL25: 380050.88 | BM25: 529170.75 | BR25: 46-50 | BS25: 16406.5 | BT25: 19869.3 | BU25: 25359.4 | BV25: 28275.5 | BW25: 30509.6 | BX25: 37105.2 | BY25: 40558.1 | BZ25: 43554.5 | CA25: 48683.8 | CB25: 60489 | CC25: 102325.3 | CD25: 129254.4 | CE25: 160165.5 | CF25: 192805.8 | CG25: 238785.8 | CH25: 290270.2 | CI25: 350439.1 | CJ25: 487856.6 | CO25: 46-50 | CP25: 15112.85 | CQ25: 18296.74 | CR25: 23363.06 | CS25: 26043.37 | CT25: 28096.93 | CU25: 34179.13 | CV25: 37354.3 | CW25: 40109.82 | CX25: 44826.25 | CY25: 55681.56 | CZ25: 94150.93 | DA25: 118913.55 | DB25: 147336.39 | DC25: 177507.59 | DD25: 219786.51 | DE25: 267127.39 | DF25: 322454.7 | DG25: 448814.04
A26: 18-24 | B26: 18 Years | C26: 24 Years | D26: 5 | E26: FLOATER | F26: 3 | G26: 1 | H26: 2 | I26: 1 | J26: Zone 1 | K26: =G26&"+"&H26 -> 1+2 | L26: =VLOOKUP(A26,'ZONE 1 PREMIUM'!$A$4:$N$16,14,0) -> 2 | M26: =VLOOKUP(D26,DROPDOWN!B:C,2,0) -> 4 | N26: =VLOOKUP(K26,$AQ$3:$AR$12,2,0) -> X35:AP46 | O26: =INDEX(INDIRECT(N26),L26,M26) -> 21185.3 | Q26: Personal Accident | R26: =IF('CALCULATOR CARE V6'!B26="YES",'optional benefits'!B123*'CALCULATOR CARE V6'!C26,0) -> 0 | U26: =VLOOKUP('CALCULATOR CARE V6'!H8,DROPDOWN!$K:$N,4,0) -> Upto 45 Years | V26: =IF('CALCULATOR CARE V6'!I8="YES",VLOOKUP(U26,'optional benefits'!$A$115:$C$118,2,0)*$W$20,0) -> 0 | W26: =IF('CALCULATOR CARE V6'!I8="yes",INDEX('ADD SI'!$B$45:$AB$49,MATCH('CARE SHEET'!U26,'ADD SI'!$B$45:$B$49,0),MATCH('CARE SHEET'!$T$3,'ADD SI'!$B$45:$Q$45,0)),0) -> 0 | X26: 51-55 | Y26: 26252.2 | Z26: 31911.35 | AA26: 40040.7 | AB26: 44779.85 | AC26: 48392 | AD26: 58789.15 | AE26: 64393.1 | AF26: 69278.3 | AG26: 77572.1 | AH26: 96602.3 | AI26: 171071.7 | AJ26: 214895.9 | AK26: 265280.85 | AL26: 307837.75 | AM26: 382437.1 | AN26: 466134.1 | AO26: 564093.4 | AP26: 787464.8 | AU26: 51-55 | AV26: 23297.625 | AW26: 28308.375 | AX26: 35546.625 | AY26: 39739.5 | AZ26: 42939 | BA26: 52182 | BB26: 57143.25 | BC26: 61470 | BD26: 68815.125 | BE26: 85666.5 | BF26: 151611.75 | BG26: 190418.62 | BH26: 235036.12 | BI26: 272981.25 | BJ26: 339041.25 | BK26: 413156.25 | BL26: 499902.75 | BM26: 697704.75 | BR26: 51-55 | BS26: 21495.1 | BT26: 26114 | BU26: 32803.1 | BV26: 36666.3 | BW26: 39614.3 | BX26: 48150.3 | BY26: 52723 | BZ26: 56710.5 | CA26: 63478.8 | CB26: 79007.5 | CC26: 139777 | CD26: 175539.1 | CE26: 216654.9 | CF26: 251758.1 | CG26: 312634.3 | CH26: 380932.2 | CI26: 460870.3 | CJ26: 643149.1 | CO26: 51-55 | CP26: 19792.22 | CQ26: 24038.86 | CR26: 30210.44 | CS26: 33760.57 | CT26: 36471.4 | CU26: 44341.2 | CV26: 48545.33 | CW26: 52212.09 | CX26: 58434.9 | CY26: 72713.9 | CZ26: 128593.84 | DA26: 161476.96 | DB26: 199284.7 | DC26: 231700.21 | DD26: 287678.25 | DE26: 350479.69 | DF26: 423984.93 | DG26: 591594.23
A27: 25-35 | B27: 25 Years | C27: 35 Years | D27: 5 | E27: FLOATER | F27: 3 | G27: 1 | H27: 2 | I27: 1 | J27: Zone 1 | K27: =G27&"+"&H27 -> 1+2 | L27: =VLOOKUP(A27,'ZONE 1 PREMIUM'!$A$4:$N$16,14,0) -> 3 | M27: =VLOOKUP(D27,DROPDOWN!B:C,2,0) -> 4 | N27: =VLOOKUP(K27,$AQ$3:$AR$12,2,0) -> X35:AP46 | O27: =INDEX(INDIRECT(N27),L27,M27) -> 22760.8 | Q27: DEDUCTIBLE | R27: =INDEX('optional benefits'!C133:V140,MATCH('CALCULATOR CARE V6'!C27,'optional benefits'!B133:B140,0),MATCH('CALCULATOR CARE V6'!B6,'optional benefits'!C132:V132,0)) -> 0.0025 | S27: =IF('CALCULATOR CARE V6'!B27="YES",1-'CARE SHEET'!R27,1) -> 1 | X27: 56-60 | Y27: 35308.45 | Z27: 42972.05 | AA27: 54439.85 | AB27: 59231.9 | AC27: 64081.45 | AD27: 78394.35 | AE27: 85947.55 | AF27: 91646.95 | AG27: 102737.55 | AH27: 128088.15 | AI27: 227176.75 | AJ27: 285693.35 | AK27: 353165 | AL27: 407562.3 | AM27: 507368.5 | AN27: 619609.65 | AO27: 751212.2 | AP27: 1050733.1 | AU27: 56-60 | AV27: 31327.875 | AW27: 38115 | AX27: 48318.75 | AY27: 52558.875 | AZ27: 56854.125 | BA27: 69574.5 | BB27: 76263.75 | BC27: 81309.375 | BD27: 91131.75 | BE27: 113580 | BF27: 201325.5 | BG27: 253143 | BH27: 312891.75 | BI27: 361337.62 | BJ27: 449717.62 | BK27: 549111.38 | BL27: 665649 | BM27: 930883.5 | BR27: 56-60 | BS27: 28902.5 | BT27: 35156 | BU27: 44585.2 | BV27: 48490.2 | BW27: 52448 | BX27: 64194.9 | BY27: 70359.3 | BZ27: 75010.1 | CA27: 84060.9 | CB27: 104746.4 | CC27: 185606.3 | CD27: 233357.3 | CE27: 288416.7 | CF27: 333204.3 | CG27: 414649.4 | CH27: 506242 | CI27: 613633.9 | CJ27: 858052.8 | CO27: 56-60 | CP27: 26609.08 | CQ27: 32359.92 | CR27: 41055.94 | CS27: 44645.31 | CT27: 48284.82 | CU27: 59110.7 | CV27: 64778.7 | CW27: 69054.77 | CX27: 77378.01 | CY27: 96399.6 | CZ27: 170751.77 | DA27: 214660.24 | DB27: 265288.56 | DC27: 306618.09 | DD27: 381507.63 | DE27: 465729.75 | DF27: 564479.39 | DG27: 789228.67
A28: 36-40 | B28: 36 Years | C28: 40 Years | D28: 5 | E28: FLOATER | F28: 3 | G28: 1 | H28: 2 | I28: 1 | J28: Zone 1 | K28: =G28&"+"&H28 -> 1+2 | L28: =VLOOKUP(A28,'ZONE 1 PREMIUM'!$A$4:$N$16,14,0) -> 4 | M28: =VLOOKUP(D28,DROPDOWN!B:C,2,0) -> 4 | N28: =VLOOKUP(K28,$AQ$3:$AR$12,2,0) -> X35:AP46 | O28: =INDEX(INDIRECT(N28),L28,M28) -> 26272.9 | Q28: GLOBAL COVERAGE TOTAL | R28: =HLOOKUP('CALCULATOR CARE V6'!B6,'optional benefits'!B99:F100,2,0) -> 0.4 | S28: =IF('CALCULATOR CARE V6'!B28="YES",S31*'CARE SHEET'!R28,0) -> 0 | U28: =V21+SUM(V22:V26)*95% -> 413.08982 | V28: =V21+V22*95%+V23*95%+V24*95%+V25*95%+V26*95% -> 413.08982 | W28: =W21+SUM(W22:W26)*97.5% -> #N/A | X28: 61-65 | Y28: 48477.1 | Z28: 59098.5 | AA28: 73485 | AB28: 82624.05 | AC28: 89534.4 | AD28: 108111.5 | AE28: 118692.65 | AF28: 126257.35 | AG28: 141784.65 | AH28: 177127.6 | AI28: 314112.15 | AJ28: 395849.55 | AK28: 490394.5 | AL28: 563348.2 | AM28: 703052.5 | AN28: 860584.1 | AO28: 1045647.8 | AP28: 1465986.6 | AU28: 61-65 | AV28: 42991.875 | AW28: 52398 | AX28: 65187 | AY28: 73276.875 | AZ28: 79395.75 | BA28: 95895 | BB28: 105264 | BC28: 111963.38 | BD28: 125713.12 | BE28: 157010.62 | BF28: 278313.75 | BG28: 350696.25 | BH28: 434417.62 | BI28: 499295.25 | BJ28: 623008.12 | BK28: 762507 | BL28: 926385.75 | BM28: 1298608.9 | BR28: 61-65 | BS28: 39651.7 | BT28: 48319.7 | BU28: 60131.5 | BV28: 67584 | BW28: 73222.6 | BX28: 88452.1 | BY28: 97087.1 | BZ28: 103260.3 | CA28: 115931.2 | CB28: 144771 | CC28: 256555.2 | CD28: 323255.9 | CE28: 400407.7 | CF28: 460339 | CG28: 574343 | CH28: 702893.4 | CI28: 853911.3 | CJ28: 1196921 | CO28: 61-65 | CP28: 36495.38 | CQ28: 44466.55 | CR28: 55352.38 | CS28: 62204.12 | CT28: 67389.25 | CU28: 81418.64 | CV28: 89358.2 | CW28: 95034.92 | CX28: 106685.93 | CY28: 133205.63 | CZ28: 235993.72 | DA28: 297326.93 | DB28: 368269.58 | DC28: 423523.86 | DD28: 528353.52 | DE28: 646558.57 | DF28: 785423.48 | DG28: 1100830.2
A29: 41-45 | B29: 41 Years | C29: 45 Years | D29: 5 | E29: FLOATER | F29: 3 | G29: 1 | H29: 2 | I29: 1 | J29: Zone 1 | K29: =G29&"+"&H29 -> 1+2 | L29: =VLOOKUP(A29,'ZONE 1 PREMIUM'!$A$4:$N$16,14,0) -> 5 | M29: =VLOOKUP(D29,DROPDOWN!B:C,2,0) -> 4 | N29: =VLOOKUP(K29,$AQ$3:$AR$12,2,0) -> X35:AP46 | O29: =INDEX(INDIRECT(N29),L29,M29) -> 29431.95 | Q29: EXT OF GLOBAL COVERAGE | R29: =IF('CALCULATOR CARE V6'!C29=U34,'CARE SHEET'!V34,'CARE SHEET'!V35) -> 0.1 | S29: =IF('CALCULATOR CARE V6'!B29="YES",S32*'CARE SHEET'!R29,0) -> 0 | V29: AAHC | X29: 66-70 | Y29: 61397.35 | Z29: 74982.3 | AA29: 95891.6 | AB29: 104613.2 | AC29: 113522.25 | AD29: 136746.5 | AE29: 150382.05 | AF29: 162363.9 | AG29: 182611.95 | AH29: 228513.05 | AI29: 396721.25 | AJ29: 502570.7 | AK29: 625382.65 | AL29: 726580.35 | AM29: 908859.95 | AN29: 1114916.9 | AO29: 1357442.8 | AP29: 1907211.7 | AU29: 66-70 | AV29: 54432 | AW29: 66461.625 | AX29: 85027.5 | AY29: 92746.125 | AZ29: 100635.75 | BA29: 121249.12 | BB29: 133327.12 | BC29: 143938.12 | BD29: 161868.38 | BE29: 202514.62 | BF29: 351475.88 | BG29: 445208.62 | BH29: 553962.38 | BI29: 643801.5 | BJ29: 805215.38 | BK29: 987684.75 | BL29: 1202448.4 | BM29: 1689286.5 | BR29: 66-70 | BS29: 50193 | BT29: 61278.8 | BU29: 78413.5 | BV29: 85525 | BW29: 92796 | BX29: 111815 | BY29: 122947 | BZ29: 132724.9 | CA29: 149248 | CB29: 186705.2 | CC29: 323979.7 | CD29: 410357.2 | CE29: 510574.9 | CF29: 593481.9 | CG29: 742228.3 | CH29: 910376.5 | CI29: 1108286.3 | CJ29: 1556915.8 | CO29: 66-70 | CP29: 46186.57 | CQ29: 56380.25 | CR29: 72163.45 | CS29: 78700.18 | CT29: 85386.24 | CU29: 102900.36 | CV29: 113137.64 | CW29: 122129.05 | CX29: 137322.56 | CY29: 171765.47 | CZ29: 297996.19 | DA29: 377422.31 | DB29: 469575.27 | DC29: 545930.86 | DD29: 682706.24 | DE29: 837322.74 | DF29: 1019305.9 | DG29: 1431831.6
A30: 46-50 | B30: 46 Years | C30: 50 Years | D30: 5 | E30: FLOATER | F30: 3 | G30: 1 | H30: 2 | I30: 1 | J30: Zone 1 | K30: =G30&"+"&H30 -> 1+2 | L30: =VLOOKUP(A30,'ZONE 1 PREMIUM'!$A$4:$N$16,14,0) -> 6 | M30: =VLOOKUP(D30,DROPDOWN!B:C,2,0) -> 4 | N30: =VLOOKUP(K30,$AQ$3:$AR$12,2,0) -> X35:AP46 | O30: =INDEX(INDIRECT(N30),L30,M30) -> 36417.05 | Q30: TRAVEL PLUS | R30: =IF('CALCULATOR CARE V6'!B30="yes",'TRAVEL PLUS'!N14*S14*S15,0) -> 0 | V30: =IF('CALCULATOR CARE V6'!C25='optional benefits'!B93,'optional benefits'!C93,'optional benefits'!C94) -> 268.53197 | X30: 71-75 | Y30: 73238.9 | Z30: 89573.5 | AA30: 112788.55 | AB30: 123257 | AC30: 133919.8 | AD30: 161249.55 | AE30: 177534.7 | AF30: 191910.85 | AG30: 216127.55 | AH30: 270820.4 | AI30: 457637.9 | AJ30: 583213.3 | AK30: 729319.65 | AL30: 862299.9 | AM30: 1080508.9 | AN30: 1327733.6 | AO30: 1619209.2 | AP30: 2278725 | AU30: 71-75 | AV30: 64918.125 | AW30: 79383.375 | AX30: 99990 | AY30: 109256.62 | AZ30: 118699.88 | BA30: 142947 | BB30: 157371.75 | BC30: 170103.38 | BD30: 191548.12 | BE30: 239979.38 | BF30: 405419.62 | BG30: 516621.38 | BH30: 646002 | BI30: 763979.62 | BJ30: 957210.75 | BK30: 1176134.6 | BL30: 1434245.6 | BM30: 2018265.8 | BR30: 71-75 | BS30: 59857.6 | BT30: 73187.4 | BU30: 92202 | BV30: 100740.2 | BW30: 109441.2 | BX30: 131810.8 | BY30: 145105.4 | BZ30: 156836.9 | CA30: 176599.5 | CB30: 221229.8 | CC30: 373690.9 | CD30: 476164.7 | CE30: 595391.5 | CF30: 704225.5 | CG30: 882291.3 | CH30: 1084034.6 | CI30: 1321888.7 | CJ30: 1860074.7 | CO30: 71-75 | CP30: 55074.43 | CQ30: 67331.48 | CR30: 84842.33 | CS30: 92690.33 | CT30: 100692.02 | CU30: 121286.48 | CV30: 133513.01 | CW30: 144300.74 | CX30: 162472.13 | CY30: 203511.72 | CZ30: 343707.52 | DA30: 437934.75 | DB30: 547565.86 | DC30: 647758.66 | DD30: 811495.19 | DE30: 997003.38 | DF30: 1215715.2 | DG30: 1710591.5
A31: 51-55 | B31: 51 Years | C31: 55 Years | D31: 5 | E31: FLOATER | F31: 3 | G31: 1 | H31: 2 | I31: 1 | J31: Zone 1 | K31: =G31&"+"&H31 -> 1+2 | L31: =VLOOKUP(A31,'ZONE 1 PREMIUM'!$A$4:$N$16,14,0) -> 7 | M31: =VLOOKUP(D31,DROPDOWN!B:C,2,0) -> 4 | N31: =VLOOKUP(K31,$AQ$3:$AR$12,2,0) -> X35:AP46 | O31: =INDEX(INDIRECT(N31),L31,M31) -> 46790.05 | R31: =R11*S12*S13*S14*S15*S16*S17*S27+R18+R19+R20+R21+R22+R23+R24+R25+R26+S28+S29+R30+R32 -> 196386.14 | S31: =R11*S14*S15*S17*S27 -> 149487.64 | V31: =V30*'CALCULATOR CARE V6'!J10 -> 268.53197 | X31: 75+ | Y31: 97856.95 | Z31: 119855.3 | AA31: 152572.8 | AB31: 167082.35 | AC31: 181792 | AD31: 218673.65 | AE31: 241063 | AF31: 260923.5 | AG31: 294289.6 | AH31: 369338.6 | AI31: 606031.6 | AJ31: 777609.3 | AK31: 977864.55 | AL31: 1177658.6 | AM31: 1478545.8 | AN31: 1820271.7 | AO31: 2223910.2 | AP31: 3135399.1 | AU31: 75+ | AV31: 86720.625 | AW31: 106201.12 | AX31: 135223.88 | AY31: 148069.12 | AZ31: 161094.38 | BA31: 193803.75 | BB31: 213633 | BC31: 231220.12 | BD31: 260767.12 | BE31: 327225.38 | BF31: 536833.12 | BG31: 688770 | BH31: 866101.5 | BI31: 1043251.9 | BJ31: 1309696.9 | BK31: 1612305 | BL31: 1969738.9 | BM31: 2776889.2 | BR31: 75+ | BS31: 79949.1 | BT31: 97900 | BU31: 124672.9 | BV31: 136507.8 | BW31: 148511 | BX31: 178678.5 | BY31: 196953.9 | BZ31: 213161.3 | CA31: 240389.6 | CB31: 301632.1 | CC31: 494793.2 | CD31: 634805.6 | CE31: 798220.5 | CF31: 961587 | CG31: 1207121.3 | CH31: 1485980.1 | CI31: 1815361.9 | CJ31: 2559167.6 | CO31: 75+ | CP31: 73549.93 | CQ31: 90055.8 | CR31: 114701.79 | CS31: 125583.26 | CT31: 136619.51 | CU31: 164386.17 | CV31: 181192.88 | CW31: 196095.36 | CX31: 221131.57 | CY31: 277445.33 | CZ31: 455066.28 | DA31: 583812.72 | DB31: 734075.76 | DC31: 884416.19 | DD31: 1110191.2 | DE31: 1366609.3 | DF31: 1669484.3 | DG31: 2353431
A32: 56-60 | B32: 56 Years | C32: 60 Years | D32: 5 | E32: FLOATER | F32: 3 | G32: 1 | H32: 2 | I32: 1 | J32: Zone 1 | K32: =G32&"+"&H32 -> 1+2 | L32: =VLOOKUP(A32,'ZONE 1 PREMIUM'!$A$4:$N$16,14,0) -> 8 | M32: =VLOOKUP(D32,DROPDOWN!B:C,2,0) -> 4 | N32: =VLOOKUP(K32,$AQ$3:$AR$12,2,0) -> X35:AP46 | O32: =INDEX(INDIRECT(N32),L32,M32) -> 61353.65 | Q32: ADD SI | R32: =IF('CALCULATOR CARE V6'!B31="yes",'CARE SHEET'!V56*S27*S13*S15*S17,0) -> 0 | S32: =S31+S28 -> 149487.64
A33: 61-65 | B33: 61 Years | C33: 65 Years | D33: 5 | E33: FLOATER | F33: 3 | G33: 1 | H33: 2 | I33: 1 | J33: Zone 1 | K33: =G33&"+"&H33 -> 1+2 | L33: =VLOOKUP(A33,'ZONE 1 PREMIUM'!$A$4:$N$16,14,0) -> 9 | M33: =VLOOKUP(D33,DROPDOWN!B:C,2,0) -> 4 | N33: =VLOOKUP(K33,$AQ$3:$AR$12,2,0) -> X35:AP46 | O33: =INDEX(INDIRECT(N33),L33,M33) -> 78218.4 | V33: EXT | X33: 1A2C
A34: 66-70 | B34: 66 Years | C34: 70 Years | D34: 5 | E34: FLOATER | F34: 3 | G34: 1 | H34: 2 | I34: 1 | J34: Zone 1 | K34: =G34&"+"&H34 -> 1+2 | L34: =VLOOKUP(A34,'ZONE 1 PREMIUM'!$A$4:$N$16,14,0) -> 10 | M34: =VLOOKUP(D34,DROPDOWN!B:C,2,0) -> 4 | N34: =VLOOKUP(K34,$AQ$3:$AR$12,2,0) -> X35:AP46 | O34: =INDEX(INDIRECT(N34),L34,M34) -> 101466.8 | Q34: DA+ | R34: 1A | S34: 2 | T34: 3 | U34: EXCL US | V34: 0.05 | Y34: Care 3 | AA34: Care 4 | AD34: Care 5 | AI34: Care 6 | AL34: Care 7 | AT34: 1A2C | AV34: Care 3 | AX34: Care 4 | BA34: Care 5 | BF34: Care 6 | BI34: Care 7 | BQ34: 1A2C | BS34: Care 3 | BU34: Care 4 | BX34: Care 5 | CC34: Care 6 | CF34: Care 7 | CN34: 1A2C | CP34: Care 3 | CR34: Care 4 | CU34: Care 5 | CZ34: Care 6 | DC34: Care 7
A35: 71-75 | B35: 71 Years | C35: 75 Years | D35: 5 | E35: FLOATER | F35: 3 | G35: 1 | H35: 2 | I35: 1 | J35: Zone 1 | K35: =G35&"+"&H35 -> 1+2 | L35: =VLOOKUP(A35,'ZONE 1 PREMIUM'!$A$4:$N$16,14,0) -> 11 | M35: =VLOOKUP(D35,DROPDOWN!B:C,2,0) -> 4 | N35: =VLOOKUP(K35,$AQ$3:$AR$12,2,0) -> X35:AP46 | O35: =INDEX(INDIRECT(N35),L35,M35) -> 119402.2 | Q35: =VLOOKUP('CALCULATOR CARE V6'!H3,DROPDOWN!K:N,4,0) -> Upto 45 Years | R35: =IF('CALCULATOR CARE V6'!I3="YES",VLOOKUP(Q35,'optional benefits'!$E$114:$G$118,2,0)*$W$20,0) -> 378.66567 | S35: =IF('CALCULATOR CARE V6'!I3="YES",VLOOKUP(Q35,'optional benefits'!$I$114:$K$118,2,0)*$W$20,0) -> 361.45359 | T35: =IF('CALCULATOR CARE V6'!I3="YES",VLOOKUP(Q35,'optional benefits'!$M$114:$O$118,2,0)*$W$20,0) -> 344.24152 | U35: INCL US | V35: =HLOOKUP('CALCULATOR CARE V6'!B6,'optional benefits'!B110:F111,2,0) -> 0.1 | X35: Age-Band/ SI | Y35: 3L | Z35: 4L | AA35: 5L | AB35: 7L | AC35: 10L | AD35: 15L | AE35: 20L | AF35: 25L | AG35: 30L | AH35: 40L | AI35: 50L | AJ35: 60L | AK35: 75L | AL35: 1 CR | AM35: 1.5 CR | AN35: 2 CR | AO35: 3 CR | AP35: 6 CR | AU35: Age-Band/ SI | AV35: 3L | AW35: 4L | AX35: 5L | AY35: 7L | AZ35: 10L | BA35: 15L | BB35: 20L | BC35: 25L | BD35: 30L | BE35: 40L | BF35: 50L | BG35: 60L | BH35: 75L | BI35: 1 CR | BJ35: 1.5 CR | BK35: 2 CR | BL35: 3 CR | BM35: 6 CR | BR35: Age-Band/ SI | BS35: 3L | BT35: 4L | BU35: 5L | BV35: 7L | BW35: 10L | BX35: 15L | BY35: 20L | BZ35: 25L | CA35: 30L | CB35: 40L | CC35: 50L | CD35: 60L | CE35: 75L | CF35: 1 CR | CG35: 1.5 CR | CH35: 2 CR | CI35: 3 CR | CJ35: 6 CR | CO35: Age-Band/ SI | CP35: 3L | CQ35: 4L | CR35: 5L | CS35: 7L | CT35: 10L | CU35: 15L | CV35: 20L | CW35: 25L | CX35: 30L | CY35: 40L | CZ35: 50L | DA35: 60L | DB35: 75L | DC35: 1 CR | DD35: 1.5 CR | DE35: 2 CR | DF35: 3 CR | DG35: 6 CR
A36: 75+ | B36: >75 Years | D36: 5 | E36: FLOATER | F36: 3 | G36: 1 | H36: 2 | I36: 1 | J36: Zone 1 | K36: =G36&"+"&H36 -> 1+2 | L36: =VLOOKUP(A36,'ZONE 1 PREMIUM'!$A$4:$N$16,14,0) -> 12 | M36: =VLOOKUP(D36,DROPDOWN!B:C,2,0) -> 4 | N36: =VLOOKUP(K36,$AQ$3:$AR$12,2,0) -> X35:AP46 | O36: =INDEX(INDIRECT(N36),L36,M36) -> 155360.4 | Q36: =VLOOKUP('CALCULATOR CARE V6'!H4,DROPDOWN!K:N,4,0) -> Upto 45 Years | R36: =IF('CALCULATOR CARE V6'!I4="YES",VLOOKUP(Q36,'optional benefits'!$E$114:$G$118,2,0)*$W$20,0) -> 0 | S36: =IF('CALCULATOR CARE V6'!I4="YES",VLOOKUP(Q36,'optional benefits'!$I$114:$K$118,2,0)*$W$20,0) -> 0 | T36: =IF('CALCULATOR CARE V6'!I4="YES",VLOOKUP(Q36,'optional benefits'!$M$114:$O$118,2,0)*$W$20,0) -> 0 | X36: 18-24 | Y36: 14478.5 | Z36: 17558.2 | AA36: 21185.3 | AB36: 23100.05 | AC36: 24856.1 | AD36: 31535.3 | AE36: 34524.15 | AF36: 37113.95 | AG36: 41389.65 | AH36: 51360.15 | AI36: 94318.4 | AJ36: 115729.1 | AK36: 139752.6 | AL36: 200990.1 | AM36: 239764.65 | AN36: 282519.35 | AO36: 332002.7 | AP36: 445818.2 | AU36: 18-24 | AV36: 12853.125 | AW36: 15579 | AX36: 18806.625 | AY36: 20502 | AZ36: 22056.75 | BA36: 27985.5 | BB36: 30632.625 | BC36: 32926.5 | BD36: 36712.125 | BE36: 45541.125 | BF36: 83581.875 | BG36: 102541.5 | BH36: 123815.25 | BI36: 178906.5 | BJ36: 213242.62 | BK36: 251103.38 | BL36: 294922.12 | BM36: 395708.62 | BR36: 18-24 | BS36: 11860.2 | BT36: 14373.7 | BU36: 17354.7 | BV36: 18916.7 | BW36: 20350 | BX36: 25821.4 | BY36: 28261.2 | BZ36: 30374.3 | CA36: 33862.4 | CB36: 41999.1 | CC36: 77053.9 | CD36: 94526.3 | CE36: 114130.5 | CF36: 165352 | CG36: 196993.5 | CH36: 231883.3 | CI36: 272262.1 | CJ36: 365139.5 | CO36: 18-24 | CP36: 10922.89 | CQ36: 13233.69 | CR36: 15982.67 | CS36: 17419.29 | CT36: 18737.1 | CU36: 23775.08 | CV36: 26018.3 | CW36: 27961.77 | CX36: 31169.64 | CY36: 38651.4 | CZ36: 70885.97 | DA36: 86951.48 | DB36: 104977.9 | DC36: 152537.87 | DD36: 181632.15 | DE36: 213714.12 | DF36: 250843.88 | DG36: 336247.56
